<?xml version="1.0" encoding="UTF-8"?>
<!-- Generated by org.testng.reporters.JUnitReportReporter -->
<testsuite hostname="ULVMCTMTTL107" name="Testscript.NumberHosting" tests="52" failures="1" timestamp="25 Oct 2019 09:12:48 GMT" time="5843.446" errors="5">
  <testcase name="NumberInquiry" time="20.181" classname="Testscript.NumberHosting"/>
  <testcase name="NumberInquiry" time="39.155" classname="Testscript.NumberHosting"/>
  <testcase name="NumberInquiry" time="102.463" classname="Testscript.NumberHosting"/>
  <testcase name="NumberInquiry" time="17.915" classname="Testscript.NumberHosting"/>
  <testcase name="NumberInquiry" time="52.734" classname="Testscript.NumberHosting"/>
  <testcase name="NumberInquiry" time="19.238" classname="Testscript.NumberHosting"/>
  <testcase name="NumberInquiry" time="409.603" classname="Testscript.NumberHosting"/>
  <testcase name="NumberInquiry" time="16.367" classname="Testscript.NumberHosting"/>
  <testcase name="NumberInquiry" time="99.676" classname="Testscript.NumberHosting">
    <failure type="org.openqa.selenium.StaleElementReferenceException" message="stale element reference: element is not attached to the page document
  (Session info: chrome=77.0.3865.120)
  (Driver info: chromedriver=2.40.565498 (ea082db3280dd6843ebfb08a625e3eb905c4f5ab),platform=Windows NT 10.0.14393 x86_64) (WARNING: The server did not provide any stacktrace information)
Command duration or timeout: 7 milliseconds
For documentation on this error, please visit: http://seleniumhq.org/exceptions/stale_element_reference.html
Build info: version: &#039;3.4.0&#039;, revision: &#039;unknown&#039;, time: &#039;unknown&#039;
System info: host: &#039;ULVMCTMTTL107&#039;, ip: &#039;10.100.19.57&#039;, os.name: &#039;Windows Server 2016&#039;, os.arch: &#039;amd64&#039;, os.version: &#039;10.0&#039;, java.version: &#039;1.8.0_221&#039;
Driver info: org.openqa.selenium.chrome.ChromeDriver
Capabilities [{applicationCacheEnabled=false, rotatable=false, mobileEmulationEnabled=false, networkConnectionEnabled=false, chrome={chromedriverVersion=2.40.565498 (ea082db3280dd6843ebfb08a625e3eb905c4f5ab), userDataDir=C:\Users\ASRIVA~1\AppData\Local\Temp\2\scoped_dir31384_4726}, takesHeapSnapshot=true, pageLoadStrategy=none, databaseEnabled=false, handlesAlerts=true, hasTouchScreen=false, version=77.0.3865.120, platform=XP, browserConnectionEnabled=false, nativeEvents=true, acceptSslCerts=false, acceptInsecureCerts=false, locationContextEnabled=true, webStorageEnabled=true, browserName=chrome, takesScreenshot=true, javascriptEnabled=true, cssSelectorsEnabled=true, setWindowRect=true, unexpectedAlertBehaviour=}]
Session ID: ca0896f73ac828a597273f0bbdc5ae99">
      <![CDATA[org.openqa.selenium.StaleElementReferenceException: stale element reference: element is not attached to the page document
  (Session info: chrome=77.0.3865.120)
  (Driver info: chromedriver=2.40.565498 (ea082db3280dd6843ebfb08a625e3eb905c4f5ab),platform=Windows NT 10.0.14393 x86_64) (WARNING: The server did not provide any stacktrace information)
Command duration or timeout: 7 milliseconds
For documentation on this error, please visit: http://seleniumhq.org/exceptions/stale_element_reference.html
Build info: version: '3.4.0', revision: 'unknown', time: 'unknown'
System info: host: 'ULVMCTMTTL107', ip: '10.100.19.57', os.name: 'Windows Server 2016', os.arch: 'amd64', os.version: '10.0', java.version: '1.8.0_221'
Driver info: org.openqa.selenium.chrome.ChromeDriver
Capabilities [{applicationCacheEnabled=false, rotatable=false, mobileEmulationEnabled=false, networkConnectionEnabled=false, chrome={chromedriverVersion=2.40.565498 (ea082db3280dd6843ebfb08a625e3eb905c4f5ab), userDataDir=C:\Users\ASRIVA~1\AppData\Local\Temp\2\scoped_dir31384_4726}, takesHeapSnapshot=true, pageLoadStrategy=none, databaseEnabled=false, handlesAlerts=true, hasTouchScreen=false, version=77.0.3865.120, platform=XP, browserConnectionEnabled=false, nativeEvents=true, acceptSslCerts=false, acceptInsecureCerts=false, locationContextEnabled=true, webStorageEnabled=true, browserName=chrome, takesScreenshot=true, javascriptEnabled=true, cssSelectorsEnabled=true, setWindowRect=true, unexpectedAlertBehaviour=}]
Session ID: ca0896f73ac828a597273f0bbdc5ae99
	at sun.reflect.GeneratedConstructorAccessor24.newInstance(Unknown Source)
	at sun.reflect.DelegatingConstructorAccessorImpl.newInstance(Unknown Source)
	at java.lang.reflect.Constructor.newInstance(Unknown Source)
	at org.openqa.selenium.remote.ErrorHandler.createThrowable(ErrorHandler.java:215)
	at org.openqa.selenium.remote.ErrorHandler.throwIfResponseFailed(ErrorHandler.java:167)
	at org.openqa.selenium.remote.RemoteWebDriver.execute(RemoteWebDriver.java:671)
	at org.openqa.selenium.remote.RemoteWebElement.execute(RemoteWebElement.java:272)
	at org.openqa.selenium.remote.RemoteWebElement.getText(RemoteWebElement.java:156)
	at Driver.DriverHelper.Gettext(DriverHelper.java:818)
	at ScriptHelper.NumberHostingHelper.NumberQuiryUsingNumberStatus(NumberHostingHelper.java:714)
	at ScriptHelper.NumberHostingHelper.Search(NumberHostingHelper.java:73)
	at Testscript.NumberHosting.NumberInquiry(NumberHosting.java:16)
	at sun.reflect.GeneratedMethodAccessor5.invoke(Unknown Source)
	at sun.reflect.DelegatingMethodAccessorImpl.invoke(Unknown Source)
	at java.lang.reflect.Method.invoke(Unknown Source)
	at org.testng.internal.MethodInvocationHelper.invokeMethod(MethodInvocationHelper.java:84)
	at org.testng.internal.Invoker.invokeMethod(Invoker.java:714)
	at org.testng.internal.Invoker.invokeTestMethod(Invoker.java:901)
	at org.testng.internal.Invoker.invokeTestMethods(Invoker.java:1231)
	at org.testng.internal.TestMethodWorker.invokeTestMethods(TestMethodWorker.java:127)
	at org.testng.internal.TestMethodWorker.run(TestMethodWorker.java:111)
	at org.testng.TestRunner.privateRun(TestRunner.java:767)
	at org.testng.TestRunner.run(TestRunner.java:617)
	at org.testng.SuiteRunner.runTest(SuiteRunner.java:334)
	at org.testng.SuiteRunner.runSequentially(SuiteRunner.java:329)
	at org.testng.SuiteRunner.privateRun(SuiteRunner.java:291)
	at org.testng.SuiteRunner.run(SuiteRunner.java:240)
	at org.testng.SuiteRunnerWorker.runSuite(SuiteRunnerWorker.java:52)
	at org.testng.SuiteRunnerWorker.run(SuiteRunnerWorker.java:86)
	at org.testng.TestNG.runSuitesSequentially(TestNG.java:1224)
	at org.testng.TestNG.runSuitesLocally(TestNG.java:1149)
	at org.testng.TestNG.run(TestNG.java:1057)
	at org.testng.remote.AbstractRemoteTestNG.run(AbstractRemoteTestNG.java:115)
	at org.testng.remote.RemoteTestNG.initAndRun(RemoteTestNG.java:251)
	at org.testng.remote.RemoteTestNG.main(RemoteTestNG.java:77)
]]>
    </failure>
  </testcase> <!-- NumberInquiry -->
  <testcase name="NumberInquiry" time="46.047" classname="Testscript.NumberHosting"/>
  <testcase name="NumberInquiry" time="105.331" classname="Testscript.NumberHosting"/>
  <testcase name="NumberInquiry" time="24.071" classname="Testscript.NumberHosting"/>
  <testcase name="NumberInquiry" time="308.680" classname="Testscript.NumberHosting"/>
  <testcase name="NumberInquiry" time="21.024" classname="Testscript.NumberHosting"/>
  <testcase name="NumberInquiry" time="22.945" classname="Testscript.NumberHosting">
    <error type="java.lang.AssertionError" message=" &lt;font color=&#039;red&#039;&gt; Either data is incorrect in excel sheet or no Record found in system Application &lt;/font&gt;">
      <![CDATA[java.lang.AssertionError:  <font color='red'> Either data is incorrect in excel sheet or no Record found in system Application </font>
	at org.testng.Assert.fail(Assert.java:94)
	at Driver.DriverHelper.RedLog(DriverHelper.java:1087)
	at ScriptHelper.NumberHostingHelper.NumberQuiryUsingNumberStatus(NumberHostingHelper.java:668)
	at ScriptHelper.NumberHostingHelper.Search(NumberHostingHelper.java:73)
	at Testscript.NumberHosting.NumberInquiry(NumberHosting.java:16)
	at sun.reflect.GeneratedMethodAccessor5.invoke(Unknown Source)
	at sun.reflect.DelegatingMethodAccessorImpl.invoke(Unknown Source)
	at java.lang.reflect.Method.invoke(Unknown Source)
	at org.testng.internal.MethodInvocationHelper.invokeMethod(MethodInvocationHelper.java:84)
	at org.testng.internal.Invoker.invokeMethod(Invoker.java:714)
	at org.testng.internal.Invoker.invokeTestMethod(Invoker.java:901)
	at org.testng.internal.Invoker.invokeTestMethods(Invoker.java:1231)
	at org.testng.internal.TestMethodWorker.invokeTestMethods(TestMethodWorker.java:127)
	at org.testng.internal.TestMethodWorker.run(TestMethodWorker.java:111)
	at org.testng.TestRunner.privateRun(TestRunner.java:767)
	at org.testng.TestRunner.run(TestRunner.java:617)
	at org.testng.SuiteRunner.runTest(SuiteRunner.java:334)
	at org.testng.SuiteRunner.runSequentially(SuiteRunner.java:329)
	at org.testng.SuiteRunner.privateRun(SuiteRunner.java:291)
	at org.testng.SuiteRunner.run(SuiteRunner.java:240)
	at org.testng.SuiteRunnerWorker.runSuite(SuiteRunnerWorker.java:52)
	at org.testng.SuiteRunnerWorker.run(SuiteRunnerWorker.java:86)
	at org.testng.TestNG.runSuitesSequentially(TestNG.java:1224)
	at org.testng.TestNG.runSuitesLocally(TestNG.java:1149)
	at org.testng.TestNG.run(TestNG.java:1057)
	at org.testng.remote.AbstractRemoteTestNG.run(AbstractRemoteTestNG.java:115)
	at org.testng.remote.RemoteTestNG.initAndRun(RemoteTestNG.java:251)
	at org.testng.remote.RemoteTestNG.main(RemoteTestNG.java:77)
]]>
    </error>
  </testcase> <!-- NumberInquiry -->
  <testcase name="NumberInquiry" time="19.662" classname="Testscript.NumberHosting"/>
  <testcase name="NumberInquiry" time="97.908" classname="Testscript.NumberHosting"/>
  <testcase name="NumberInquiry" time="46.607" classname="Testscript.NumberHosting"/>
  <testcase name="NumberInquiry" time="19.600" classname="Testscript.NumberHosting"/>
  <testcase name="NumberInquiry" time="25.874" classname="Testscript.NumberHosting"/>
  <testcase name="NumberInquiry" time="19.544" classname="Testscript.NumberHosting"/>
  <testcase name="NumberInquiry" time="18.065" classname="Testscript.NumberHosting"/>
  <testcase name="NumberInquiry" time="20.854" classname="Testscript.NumberHosting">
    <error type="java.lang.AssertionError" message=" &lt;font color=&#039;red&#039;&gt; Either data is incorrect in excel sheet or no Record found in system Application &lt;/font&gt;">
      <![CDATA[java.lang.AssertionError:  <font color='red'> Either data is incorrect in excel sheet or no Record found in system Application </font>
	at org.testng.Assert.fail(Assert.java:94)
	at Driver.DriverHelper.RedLog(DriverHelper.java:1087)
	at ScriptHelper.NumberHostingHelper.NumberQuiryUsingNumberStatus(NumberHostingHelper.java:668)
	at ScriptHelper.NumberHostingHelper.Search(NumberHostingHelper.java:73)
	at Testscript.NumberHosting.NumberInquiry(NumberHosting.java:16)
	at sun.reflect.GeneratedMethodAccessor5.invoke(Unknown Source)
	at sun.reflect.DelegatingMethodAccessorImpl.invoke(Unknown Source)
	at java.lang.reflect.Method.invoke(Unknown Source)
	at org.testng.internal.MethodInvocationHelper.invokeMethod(MethodInvocationHelper.java:84)
	at org.testng.internal.Invoker.invokeMethod(Invoker.java:714)
	at org.testng.internal.Invoker.invokeTestMethod(Invoker.java:901)
	at org.testng.internal.Invoker.invokeTestMethods(Invoker.java:1231)
	at org.testng.internal.TestMethodWorker.invokeTestMethods(TestMethodWorker.java:127)
	at org.testng.internal.TestMethodWorker.run(TestMethodWorker.java:111)
	at org.testng.TestRunner.privateRun(TestRunner.java:767)
	at org.testng.TestRunner.run(TestRunner.java:617)
	at org.testng.SuiteRunner.runTest(SuiteRunner.java:334)
	at org.testng.SuiteRunner.runSequentially(SuiteRunner.java:329)
	at org.testng.SuiteRunner.privateRun(SuiteRunner.java:291)
	at org.testng.SuiteRunner.run(SuiteRunner.java:240)
	at org.testng.SuiteRunnerWorker.runSuite(SuiteRunnerWorker.java:52)
	at org.testng.SuiteRunnerWorker.run(SuiteRunnerWorker.java:86)
	at org.testng.TestNG.runSuitesSequentially(TestNG.java:1224)
	at org.testng.TestNG.runSuitesLocally(TestNG.java:1149)
	at org.testng.TestNG.run(TestNG.java:1057)
	at org.testng.remote.AbstractRemoteTestNG.run(AbstractRemoteTestNG.java:115)
	at org.testng.remote.RemoteTestNG.initAndRun(RemoteTestNG.java:251)
	at org.testng.remote.RemoteTestNG.main(RemoteTestNG.java:77)
]]>
    </error>
  </testcase> <!-- NumberInquiry -->
  <testcase name="NumberInquiry" time="46.159" classname="Testscript.NumberHosting"/>
  <testcase name="NumberInquiry" time="49.897" classname="Testscript.NumberHosting"/>
  <testcase name="NumberInquiry" time="42.961" classname="Testscript.NumberHosting"/>
  <testcase name="NumberInquiry" time="19.596" classname="Testscript.NumberHosting"/>
  <testcase name="NumberInquiry" time="50.537" classname="Testscript.NumberHosting"/>
  <testcase name="NumberInquiry" time="51.927" classname="Testscript.NumberHosting"/>
  <testcase name="NumberInquiry" time="593.272" classname="Testscript.NumberHosting">
    <error type="java.lang.AssertionError" message="waited 10 minute to change Status from InProgress to Complted!">
      <![CDATA[java.lang.AssertionError: waited 10 minute to change Status from InProgress to Complted!
	at org.testng.Assert.fail(Assert.java:94)
	at ScriptHelper.NumberHostingHelper.StatuQuerybyTransitionId(NumberHostingHelper.java:1392)
	at ScriptHelper.NumberHostingHelper.NumberQuiryUsingNumberStatus(NumberHostingHelper.java:945)
	at ScriptHelper.NumberHostingHelper.Search(NumberHostingHelper.java:73)
	at Testscript.NumberHosting.NumberInquiry(NumberHosting.java:16)
	at sun.reflect.GeneratedMethodAccessor5.invoke(Unknown Source)
	at sun.reflect.DelegatingMethodAccessorImpl.invoke(Unknown Source)
	at java.lang.reflect.Method.invoke(Unknown Source)
	at org.testng.internal.MethodInvocationHelper.invokeMethod(MethodInvocationHelper.java:84)
	at org.testng.internal.Invoker.invokeMethod(Invoker.java:714)
	at org.testng.internal.Invoker.invokeTestMethod(Invoker.java:901)
	at org.testng.internal.Invoker.invokeTestMethods(Invoker.java:1231)
	at org.testng.internal.TestMethodWorker.invokeTestMethods(TestMethodWorker.java:127)
	at org.testng.internal.TestMethodWorker.run(TestMethodWorker.java:111)
	at org.testng.TestRunner.privateRun(TestRunner.java:767)
	at org.testng.TestRunner.run(TestRunner.java:617)
	at org.testng.SuiteRunner.runTest(SuiteRunner.java:334)
	at org.testng.SuiteRunner.runSequentially(SuiteRunner.java:329)
	at org.testng.SuiteRunner.privateRun(SuiteRunner.java:291)
	at org.testng.SuiteRunner.run(SuiteRunner.java:240)
	at org.testng.SuiteRunnerWorker.runSuite(SuiteRunnerWorker.java:52)
	at org.testng.SuiteRunnerWorker.run(SuiteRunnerWorker.java:86)
	at org.testng.TestNG.runSuitesSequentially(TestNG.java:1224)
	at org.testng.TestNG.runSuitesLocally(TestNG.java:1149)
	at org.testng.TestNG.run(TestNG.java:1057)
	at org.testng.remote.AbstractRemoteTestNG.run(AbstractRemoteTestNG.java:115)
	at org.testng.remote.RemoteTestNG.initAndRun(RemoteTestNG.java:251)
	at org.testng.remote.RemoteTestNG.main(RemoteTestNG.java:77)
]]>
    </error>
  </testcase> <!-- NumberInquiry -->
  <testcase name="NumberInquiry" time="20.755" classname="Testscript.NumberHosting"/>
  <testcase name="NumberInquiry" time="563.266" classname="Testscript.NumberHosting"/>
  <testcase name="NumberInquiry" time="506.964" classname="Testscript.NumberHosting"/>
  <testcase name="NumberInquiry" time="19.789" classname="Testscript.NumberHosting"/>
  <testcase name="NumberInquiry" time="19.617" classname="Testscript.NumberHosting"/>
  <testcase name="NumberInquiry" time="51.650" classname="Testscript.NumberHosting"/>
  <testcase name="NumberInquiry" time="47.391" classname="Testscript.NumberHosting"/>
  <testcase name="NumberInquiry" time="24.027" classname="Testscript.NumberHosting"/>
  <testcase name="NumberInquiry" time="335.437" classname="Testscript.NumberHosting"/>
  <testcase name="NumberInquiry" time="36.293" classname="Testscript.NumberHosting">
    <error type="java.lang.AssertionError" message=" &lt;font color=&#039;red&#039;&gt; Either data is incorrect in excel sheet or no Record found in system Application &lt;/font&gt;">
      <![CDATA[java.lang.AssertionError:  <font color='red'> Either data is incorrect in excel sheet or no Record found in system Application </font>
	at org.testng.Assert.fail(Assert.java:94)
	at Driver.DriverHelper.RedLog(DriverHelper.java:1087)
	at ScriptHelper.NumberHostingHelper.NumberQuiryUsingNumberStatus(NumberHostingHelper.java:972)
	at ScriptHelper.NumberHostingHelper.Search(NumberHostingHelper.java:73)
	at Testscript.NumberHosting.NumberInquiry(NumberHosting.java:16)
	at sun.reflect.NativeMethodAccessorImpl.invoke0(Native Method)
	at sun.reflect.NativeMethodAccessorImpl.invoke(Unknown Source)
	at sun.reflect.DelegatingMethodAccessorImpl.invoke(Unknown Source)
	at java.lang.reflect.Method.invoke(Unknown Source)
	at org.testng.internal.MethodInvocationHelper.invokeMethod(MethodInvocationHelper.java:84)
	at org.testng.internal.Invoker.invokeMethod(Invoker.java:714)
	at org.testng.internal.Invoker.invokeTestMethod(Invoker.java:901)
	at org.testng.internal.Invoker.invokeTestMethods(Invoker.java:1231)
	at org.testng.internal.TestMethodWorker.invokeTestMethods(TestMethodWorker.java:127)
	at org.testng.internal.TestMethodWorker.run(TestMethodWorker.java:111)
	at org.testng.TestRunner.privateRun(TestRunner.java:767)
	at org.testng.TestRunner.run(TestRunner.java:617)
	at org.testng.SuiteRunner.runTest(SuiteRunner.java:334)
	at org.testng.SuiteRunner.runSequentially(SuiteRunner.java:329)
	at org.testng.SuiteRunner.privateRun(SuiteRunner.java:291)
	at org.testng.SuiteRunner.run(SuiteRunner.java:240)
	at org.testng.SuiteRunnerWorker.runSuite(SuiteRunnerWorker.java:52)
	at org.testng.SuiteRunnerWorker.run(SuiteRunnerWorker.java:86)
	at org.testng.TestNG.runSuitesSequentially(TestNG.java:1224)
	at org.testng.TestNG.runSuitesLocally(TestNG.java:1149)
	at org.testng.TestNG.run(TestNG.java:1057)
	at org.testng.remote.AbstractRemoteTestNG.run(AbstractRemoteTestNG.java:115)
	at org.testng.remote.RemoteTestNG.initAndRun(RemoteTestNG.java:251)
	at org.testng.remote.RemoteTestNG.main(RemoteTestNG.java:77)
]]>
    </error>
  </testcase> <!-- NumberInquiry -->
  <testcase name="NumberInquiry" time="556.632" classname="Testscript.NumberHosting"/>
  <testcase name="NumberInquiry" time="22.729" classname="Testscript.NumberHosting">
    <error type="java.lang.AssertionError" message=" &lt;font color=&#039;red&#039;&gt; Either data is incorrect in excel sheet or no Record found in system Application &lt;/font&gt;">
      <![CDATA[java.lang.AssertionError:  <font color='red'> Either data is incorrect in excel sheet or no Record found in system Application </font>
	at org.testng.Assert.fail(Assert.java:94)
	at Driver.DriverHelper.RedLog(DriverHelper.java:1087)
	at ScriptHelper.NumberHostingHelper.NumberQuiryUsingNumberStatus(NumberHostingHelper.java:668)
	at ScriptHelper.NumberHostingHelper.Search(NumberHostingHelper.java:73)
	at Testscript.NumberHosting.NumberInquiry(NumberHosting.java:16)
	at sun.reflect.GeneratedMethodAccessor5.invoke(Unknown Source)
	at sun.reflect.DelegatingMethodAccessorImpl.invoke(Unknown Source)
	at java.lang.reflect.Method.invoke(Unknown Source)
	at org.testng.internal.MethodInvocationHelper.invokeMethod(MethodInvocationHelper.java:84)
	at org.testng.internal.Invoker.invokeMethod(Invoker.java:714)
	at org.testng.internal.Invoker.invokeTestMethod(Invoker.java:901)
	at org.testng.internal.Invoker.invokeTestMethods(Invoker.java:1231)
	at org.testng.internal.TestMethodWorker.invokeTestMethods(TestMethodWorker.java:127)
	at org.testng.internal.TestMethodWorker.run(TestMethodWorker.java:111)
	at org.testng.TestRunner.privateRun(TestRunner.java:767)
	at org.testng.TestRunner.run(TestRunner.java:617)
	at org.testng.SuiteRunner.runTest(SuiteRunner.java:334)
	at org.testng.SuiteRunner.runSequentially(SuiteRunner.java:329)
	at org.testng.SuiteRunner.privateRun(SuiteRunner.java:291)
	at org.testng.SuiteRunner.run(SuiteRunner.java:240)
	at org.testng.SuiteRunnerWorker.runSuite(SuiteRunnerWorker.java:52)
	at org.testng.SuiteRunnerWorker.run(SuiteRunnerWorker.java:86)
	at org.testng.TestNG.runSuitesSequentially(TestNG.java:1224)
	at org.testng.TestNG.runSuitesLocally(TestNG.java:1149)
	at org.testng.TestNG.run(TestNG.java:1057)
	at org.testng.remote.AbstractRemoteTestNG.run(AbstractRemoteTestNG.java:115)
	at org.testng.remote.RemoteTestNG.initAndRun(RemoteTestNG.java:251)
	at org.testng.remote.RemoteTestNG.main(RemoteTestNG.java:77)
]]>
    </error>
  </testcase> <!-- NumberInquiry -->
  <testcase name="NumberInquiry" time="134.650" classname="Testscript.NumberHosting"/>
  <testcase name="NumberInquiry" time="560.566" classname="Testscript.NumberHosting"/>
  <testcase name="NumberInquiry" time="48.457" classname="Testscript.NumberHosting"/>
  <testcase name="NumberInquiry" time="40.990" classname="Testscript.NumberHosting"/>
  <testcase name="NumberInquiry" time="15.673" classname="Testscript.NumberHosting"/>
  <testcase name="NumberInquiry" time="50.549" classname="Testscript.NumberHosting"/>
  <testcase name="NumberInquiry" time="135.071" classname="Testscript.NumberHosting"/>
  <testcase name="NumberInquiry" time="98.198" classname="Testscript.NumberHosting"/>
  <testcase name="NumberInquiry" time="20.057" classname="Testscript.NumberHosting"/>
  <testcase name="NumberInquiry" time="106.792" classname="Testscript.NumberHosting"/>
</testsuite> <!-- Testscript.NumberHosting -->
